Workbook
Name UPDATE: 'Data Sheet'!$E$1

Sheet Summary
C1: =Financial!A2
A2: INR Cr | B2: =Financial!I3 | C2: =Financial!J3 | D2: =Financial!K3 | E2: =Financial!L3 | F2: =CONCATENATE(TEXT(Financial!M3,"MMM-YY")," e") | G2: =CONCATENATE(TEXT(Financial!N3,"MMM-YY")," e") | H2: =CONCATENATE(TEXT(Financial!O3,"MMM-YY")," e") | I2: =CONCATENATE(TEXT(B2,"YY"),"-",TEXT(E2,"YY")," 3Y CAGR") | J2: =CONCATENATE(TEXT(E2,"YY"),"-",MID(TRIM(G2), 5, 2)," 2Y CAGR") | K2: =CONCATENATE(TEXT(E2,"YY"),"-",MID(TRIM(H2), 5, 2)," 3Y CAGR") | N2: Particulars | O2: FY22A | P2: FY23A | Q2: FY24E | R2: FY25E
A3: Revenue | B3: =Financial!I9 | C3: =Financial!J9 | D3: =Financial!K9 | E3: =Financial!L9 | F3: =Financial!M9 | G3: =Financial!N9 | H3: =Financial!O9 | I3: =(E3/B3)^(1/3)-1 | J3: =(G3/E3)^(1/2)-1 | K3: =(H3/E3)^(1/3)-1 | N3: Net Revenue | O3: =D3 | P3: =E3 | Q3: =F3 | R3: =G3
A4: EBITDA | B4: =Financial!I13 | C4: =Financial!J13 | D4: =Financial!K13 | E4: =Financial!L13 | F4: =Financial!M13 | G4: =Financial!N13 | H4: =Financial!O13 | I4: =(E4/B4)^(1/3)-1 | J4: =(G4/E4)^(1/2)-1 | K4: =(H4/E4)^(1/3)-1 | N4: % Chg y-o-y | O4: =(O3-C3)/C3 | P4: =(P3-O3)/O3 | Q4: =(Q3-P3)/P3 | R4: =(R3-Q3)/Q3
A5: EBITDA Margin | B5: =Financial!I27 | C5: =Financial!J27 | D5: =Financial!K27 | E5: =Financial!L27 | F5: =Financial!M27 | G5: =Financial!N27 | H5: =Financial!O27 | N5: EBITDA | O5: =D4 | P5: =E4 | Q5: =F4 | R5: =G4
A6: PAT | B6: =Financial!I20 | C6: =Financial!J20 | D6: =Financial!K20 | E6: =Financial!L20 | F6: =Financial!M20 | G6: =Financial!N20 | H6: =Financial!O20 | I6: =(E6/B6)^(1/3)-1 | J6: =(G6/E6)^(1/2)-1 | K6: =(H6/E6)^(1/3)-1 | N6: EBITDA Margin (%) | O6: =D5 | P6: =E5 | Q6: =F5 | R6: =G5
A7: PAT Margin | B7: =Financial!I31 | C7: =Financial!J31 | D7: =Financial!K31 | E7: =Financial!L31 | F7: =Financial!M31 | G7: =Financial!N31 | H7: =Financial!O31 | N7: Net Profit | O7: =D6 | P7: =E6 | Q7: =F6 | R7: =G6
A8: EPS | B8: =Financial!I22 | C8: =Financial!J22 | D8: =Financial!K22 | E8: =Financial!L22 | F8: =Financial!M22 | G8: =Financial!N22 | H8: =Financial!O22 | I8: =(E8/B8)^(1/3)-1 | J8: =(G8/E8)^(1/2)-1 | K8: =(H8/E8)^(1/3)-1 | N8: EPS (RS) | O8: =D8 | P8: =E8 | Q8: =F8 | R8: =G8
A9: BVPS | B9: =Financial!I86 | C9: =Financial!J86 | D9: =Financial!K86 | E9: =Financial!L86 | F9: =Financial!M86 | G9: =Financial!N86 | H9: =Financial!O86 | I9: =(E9/B9)^(1/3)-1 | J9: =(G9/E9)^(1/2)-1 | K9: =(H9/E9)^(1/3)-1 | N9: EPS % Chg | O9: =(O8-C8)/C8 | P9: =(P8-O8)/O8 | Q9: =(Q8-P8)/P8 | R9: =(R8-Q8)/Q8
A10: PE | B10: ='Data Sheet'!$B$8/Summary!B8 | C10: ='Data Sheet'!$B$8/Summary!C8 | D10: ='Data Sheet'!$B$8/Summary!D8 | E10: ='Data Sheet'!$B$8/Summary!E8 | F10: ='Data Sheet'!$B$8/Summary!F8 | G10: ='Data Sheet'!$B$8/Summary!G8 | H10: ='Data Sheet'!$B$8/Summary!H8 | N10: P/E (X) | O10: =D10 | P10: =E10 | Q10: =F10 | R10: =G10
A11: P/B | B11: ='Data Sheet'!$B$8/Summary!B9 | C11: ='Data Sheet'!$B$8/Summary!C9 | D11: ='Data Sheet'!$B$8/Summary!D9 | E11: ='Data Sheet'!$B$8/Summary!E9 | F11: ='Data Sheet'!$B$8/Summary!F9 | G11: ='Data Sheet'!$B$8/Summary!G9 | H11: ='Data Sheet'!$B$8/Summary!H9 | N11: EV/EBITDA(X) | O11: =D12 | P11: =E12 | Q11: =F12 | R11: =G12
A12: EV/EBITDA | B12: =Financial!I95 | C12: =Financial!J95 | D12: =Financial!K95 | E12: =Financial!L95 | F12: =Financial!M95 | G12: =Financial!N95 | H12: =Financial!O95 | N12: P/BV | O12: =D11 | P12: =E11 | Q12: =F11 | R12: =G11
A13: RoE | B13: =Financial!I79 | C13: =Financial!J79 | D13: =Financial!K79 | E13: =Financial!L79 | F13: =Financial!M79 | G13: =Financial!N79 | H13: =Financial!O79 | N13: BV/SHARE | O13: =D9 | P13: =E9 | Q13: =F9 | R13: =G9
A14: RoCE | B14: =Financial!I80 | C14: =Financial!J80 | D14: =Financial!K80 | E14: =Financial!L80 | F14: =Financial!M80 | G14: =Financial!N80 | H14: =Financial!O80 | N14: ROE | O14: =D13 | P14: =E13 | Q14: =F13 | R14: =G13
A15: RoIC | B15: =Financial!I81 | C15: =Financial!J81 | D15: =Financial!K81 | E15: =Financial!L81 | F15: =Financial!M81 | G15: =Financial!N81 | H15: =Financial!O81 | N15: ROCE | O15: =D14 | P15: =E14 | Q15: =F14 | R15: =G14
A16: WC Sales % | B16: =Financial!I71 | C16: =Financial!J71 | D16: =Financial!K71 | E16: =Financial!L71 | F16: =Financial!M71 | G16: =Financial!N71 | H16: =Financial!O71
A17: OCF / EBITDA | B17: =Financial!I73 | C17: =Financial!J73 | D17: =Financial!K73 | E17: =Financial!L73 | F17: =Financial!M73 | G17: =Financial!N73 | H17: =Financial!O73

Sheet Valuation
A1: =Financial!A2
A2: DCF Value | B2: 10 year | F2: 3 year | G2: 0 | H2: =G2+1 | I2: =H2+1 | J2: =I2+1 | K2: =J2+1 | L2: =K2+1 | M2: =L2+1 | N2: =M2+1 | O2: =N2+1 | ... Q2: =P2+1 | S2: 4th - 7th | T2: 8th -10th
A3: DCF (Rs Cr) | B3: Hi | C3: Low | D3: Avg | E3: Median | F3: Avg | G3: FY22 | H3: FY23 | I3: FY24 | J3: FY25 | K3: FY26 | L3: FY27 | M3: FY28 | N3: FY29 | O3: FY30 | P3: FY31 | Q3: FY32
A4: Revenues | B4: =MAX(Financial!D9:L9) | C4: =MIN(Financial!D9:L9) | D4: =AVERAGE(Financial!D9:L9) | E4: =MEDIAN(Financial!D9:L9) | F4: =AVERAGE(Financial!J9:L9) | G4: =Financial!M9 | H4: =Financial!N9 | I4: =Financial!O9 | J4: =+I4*(1+J5) | K4: =+J4*(1+K5) | L4: =+K4*(1+L5) | M4: =+L4*(1+M5) | N4: =+M4*(1+N5) | O4: =+N4*(1+O5) | P4: =+O4*(1+P5) | Q4: =+P4*(1+Q5) | S4: 0.66 | T4: 0.66
A5: % yoy growth | B5: =MAX(Financial!D35:L35) | C5: =MIN(Financial!D35:L35) | D5: =AVERAGE(Financial!D35:L35) | E5: =MEDIAN(Financial!D35:L35) | F5: =AVERAGE(Financial!J35:L35) | H5: =+H4/G4-1 | I5: =+I4/H4-1 | J5: =I5 | K5: =S5 | L5: =+K5 | M5: =+L5 | N5: =+M5 | O5: =T5 | P5: =+O5 | Q5: =+P5 | S5: =J5*S4 | T5: =S5*T4
A6: EBITDA | B6: =MAX(Financial!D13:L13) | C6: =MIN(Financial!D13:L13) | D6: =AVERAGE(Financial!D13:L13) | E6: =MEDIAN(Financial!D13:L13) | F6: =AVERAGE(Financial!J13:L13) | G6: =Financial!M13 | H6: =Financial!N13 | I6: =Financial!O13 | J6: =+J7*J4 | K6: =+K7*K4 | L6: =+L7*L4 | M6: =+M7*M4 | N6: =+N7*N4 | O6: =+O7*O4 | P6: =+P7*P4 | Q6: =+Q7*Q4 | S6: 0.9 | T6: 0.9
A7: EBITDA margin | B7: =MAX(Financial!C27:L27) | C7: =MIN(Financial!C27:L27) | D7: =AVERAGE(Financial!C27:L27) | E7: =MEDIAN(Financial!C27:L27) | F7: =AVERAGE(Financial!J27:L27) | G7: =+G6/G4 | H7: =+H6/H4 | I7: =+I6/I4 | J7: =I7 | K7: =S7 | L7: =+K7 | M7: =+L7 | N7: =+M7 | O7: =T7 | P7: =+O7 | Q7: =+P7 | S7: =J7*S6 | T7: =S7*T6
A8: CFO/EBITDA | B8: =MAX(Financial!C73:L73) | C8: =MIN(Financial!C73:L73) | D8: =AVERAGE(Financial!C73:L73) | E8: =MEDIAN(Financial!C73:L73) | F8: =AVERAGE(Financial!J73:L73) | G8: =Financial!M73 | H8: =Financial!N73 | I8: =Financial!O73 | J8: =I8 | K8: =+J8 | L8: =+K8 | M8: =+L8 | N8: =+M8 | O8: =+N8 | P8: =+O8 | Q8: =+P8
A9: CFO | B9: =MAX(Financial!C64:L64) | C9: =MIN(Financial!C64:L64) | D9: =AVERAGE(Financial!C64:L64) | E9: =MEDIAN(Financial!C64:L64) | F9: =AVERAGE(Financial!J64:L64) | G9: =+G8*G6 | H9: =+H8*H6 | I9: =+I8*I6 | J9: =+J8*J6 | K9: =+K8*K6 | L9: =+L8*L6 | M9: =+M8*M6 | N9: =+N8*N6 | ... Q9: =+Q8*Q6
A10: Fixed asset turns | B10: =MAX(Financial!C72:L72) | C10: =MIN(Financial!C72:L72) | D10: =AVERAGE(Financial!C72:L72) | E10: =MEDIAN(Financial!C72:L72) | F10: =AVERAGE(Financial!J72:L72) | G10: =Financial!M72 | H10: =Financial!N72 | I10: =Financial!O72 | J10: =I10 | K10: =+J10 | L10: =+K10 | M10: =+L10 | N10: =+M10 | O10: =+N10 | P10: =+O10 | Q10: =+P10
A11: Capex | B11: =MAX(Financial!C65:L65) | C11: =MIN(Financial!C65:L65) | D11: =AVERAGE(Financial!C65:L65) | E11: =MEDIAN(Financial!C65:L65) | F11: =AVERAGE(Financial!J65:L65) | G11: =-Financial!M65 | H11: =-Financial!N65 | I11: =-Financial!O65 | J11: =-+(J4-I4)/J10 | K11: =-+(K4-J4)/K10 | L11: =-+(L4-K4)/L10 | M11: =-+(M4-L4)/M10 | N11: =-+(N4-M4)/N10 | O11: =-+(O4-N4)/O10 | P11: =-+(P4-O4)/P10 | Q11: =-+(Q4-P4)/Q10
A12: FCFF | B12: =MAX(Financial!C66:L66) | C12: =MIN(Financial!C66:L66) | D12: =AVERAGE(Financial!C66:L66) | E12: =MEDIAN(Financial!C66:L66) | F12: =AVERAGE(Financial!J66:L66) | G12: =+G9+G11 | H12: =+H9+H11 | I12: =+I9+I11 | J12: =+J9+J11 | K12: =+K9+K11 | L12: =+L9+L11 | M12: =+M9+M11 | N12: =+N9+N11 | ... Q12: =+Q9+Q11
A13: Discounting factor | G13: =1/((1+$N$17)^G2) | H13: =1/((1+$N$17)^H2) | I13: =1/((1+$N$17)^I2) | J13: =1/((1+$N$17)^J2) | K13: =1/((1+$N$17)^K2) | L13: =1/((1+$N$17)^L2) | M13: =1/((1+$N$17)^M2) | N13: =1/((1+$N$17)^N2) | ... Q13: =1/((1+$N$17)^Q2)
A14: Terminal value | Q14: =+Q12*(1+$N$18)/($N$17-$N$18)
A16: WACC calculations | H16: Cost of Equity | K16: DCF Valuations | P16: Mcap | Q16: =Financial!P6 | S16: Debt | T16: =Financial!P42
B17: =B3 | C17: =C3 | D17: =D3 | E17: =E3 | F17: =F3 | H17: Cost of Equity | J17: =J18+J19*(J20-J18) | K17: Discount rate (WACC Below) | N17: =G22 | O17: % of value | P17: CMP | Q17: =Financial!P4
A18: Debt:Equity | B18: =MAX(Financial!D76:L76) | C18: =MIN(Financial!D76:L76) | D18: =AVERAGE(Financial!D76:L76) | E18: =MEDIAN(Financial!D76:L76) | F18: =AVERAGE(Financial!J76:L76) | G18: =MAX(Financial!L76)/(1+MAX(Financial!L76)) | H18: Risk-Free Return | J18: 0.07 | K18: Terminal growth rate | N18: 0.03
A19: Cost of debt | B19: =MAX(Financial!D29:L29) | C19: =MIN(Financial!D29:L29) | D19: =AVERAGE(Financial!D29:L29) | E19: =MEDIAN(Financial!D29:L29) | F19: =AVERAGE(Financial!J29:L29) | G19: =F19+J22 | H19: Beta | J19: 2 | K19: Discounted Terminal Value | N19: =Q14*Q13 | O19: =N19/$N$22 | P19: High range | T19: Low
A20: Tax rate | G20: =AVERAGE(Financial!J30:L30) | H20: Market Return | J20: 0.12 | K20: NPV of FCFF | N20: =SUMPRODUCT(G12:Q12,G13:Q13) | O20: =N20/$N$22 | P20: PE 3Y | Q20: =MAX(Financial!J91:L91,Financial!P91) | R20: =Financial!$O$22*Q20 | S20: =R20/Financial!$P$4-1 | T20: PE 5Y | U20: =MIN(Financial!I91:L91,Financial!P91) | V20: =Financial!$O$22*U20 | W20: =V20/Financial!$P$4-1
A21: Cost of equity | G21: =J17 | K21: Net (Debt)/Cash | N21: =-Financial!L42+Financial!L47 | O21: =N21/$N$22 | P21: EV/E 3Y | Q21: =MAX(Financial!J95:L95,Financial!P95) | R21: =((Q21*Financial!$O$13)-Financial!$O$42)/Financial!$O$5 | S21: =R21/Financial!$P$4-1 | T21: EV/E 5Y | U21: =MIN(Financial!I95:L95,Financial!P95) | V21: =((U21*Financial!$O$13)-Financial!$O$42)/Financial!$O$5 | W21: =V21/Financial!$P$4-1
A22: WACC | G22: =G21*(1-G18)+((G18*G19)*(1-G20)) | H22: Inc in Int Rate | J22: 0.005 | K22: NPV | N22: =SUM(N19:N21) | O22: =SUM(O19:O21) | P22: P/S 3Y | Q22: =MAX(Financial!J96:L96,Financial!P96) | R22: =((Q22*Financial!$O$9)-Financial!$O$42)/Financial!$O$5 | S22: =R22/Financial!$P$4-1 | T22: P/S 5Y | U22: =MIN(Financial!I96:L96,Financial!P96) | V22: =((U22*Financial!$O$9)-Financial!$O$42)/Financial!$O$5 | W22: =V22/Financial!$P$4-1
K23: O/s Equity Shares | N23: =Financial!O5
K24: DCF Price | N24: =+N22/N23 | P24: DCF | R24: =N24 | S24: =R24/Financial!$P$4-1

Sheet Financial
B1: Shree Ganeshaya Namah - TIKONA CAPITAL
A2: =CONCATENATE('Data Sheet'!$B$1," Mcap ",TEXT(ROUND($P$6,0),"0,000")," Cr CMP ",TEXT($P$4,"##,##0.0")) | U2: Assumptions
C3: ='Data Sheet'!B16 | D3: ='Data Sheet'!C16 | E3: ='Data Sheet'!D16 | F3: ='Data Sheet'!E16 | G3: ='Data Sheet'!F16 | H3: ='Data Sheet'!G16 | I3: ='Data Sheet'!H16 | J3: ='Data Sheet'!I16 | ... L3: ='Data Sheet'!K16 | M3: =L3+365 | N3: =M3+365 | O3: =N3+365 | P3: TTM | Q3: 3 Yr Proj CAGR | R3: 3 Yr CAGR | S3: 5 Yr CAGR | T3: 9Yr CAGR | U3: =M3 | V3: =N3 | W3: =O3
A4: Mkt Price | B4: INR | C4: ='Data Sheet'!B90 | D4: ='Data Sheet'!C90 | E4: ='Data Sheet'!D90 | F4: ='Data Sheet'!E90 | G4: ='Data Sheet'!F90 | H4: ='Data Sheet'!G90 | I4: ='Data Sheet'!H90 | J4: ='Data Sheet'!I90 | ... L4: ='Data Sheet'!K90 | M4: =P4 | N4: =P4 | O4: =P4 | P4: ='Data Sheet'!B8 | R4: =((P4/I4)^(1/R8))-1 | S4: =((P4/G4)^(1/S8))-1 | T4: =IF(C4>0,((P4/C4)^(1/T8))-1,"-")
A5: O/s Equity Shares | B5: Cr | C5: ='Data Sheet'!B93 | D5: ='Data Sheet'!C93 | E5: ='Data Sheet'!D93 | F5: ='Data Sheet'!E93 | G5: ='Data Sheet'!F93 | H5: ='Data Sheet'!G93 | I5: ='Data Sheet'!H93 | J5: ='Data Sheet'!I93 | ... L5: ='Data Sheet'!K93 | M5: =L5 | N5: =M5 | O5: =N5 | P5: =O5 | R5: =((L5/I5)^(1/3))-1 | S5: =((L5/G5)^(1/5))-1 | T5: =IF(C5>0,((L5/C5)^(1/9))-1,"-")
A6: Mcap | B6: Cr | C6: =C4*C5 | D6: =D4*D5 | E6: =E4*E5 | F6: =F4*F5 | G6: =G4*G5 | H6: =H4*H5 | I6: =I4*I5 | J6: =J4*J5 | ... L6: =L4*L5 | M6: =P6 | N6: =P6 | O6: =P6 | P6: =P4*P5 | R6: =((L6/I6)^(1/3))-1 | S6: =((L6/G6)^(1/5))-1 | T6: =IF(C6>0,((L6/C6)^(1/9))-1,"-")
A7: Enterprise Value | B7: Cr | C7: =C6+C42 | D7: =D6+D42 | E7: =E6+E42 | F7: =F6+F42 | G7: =G6+G42 | H7: =H6+H42 | I7: =I6+I42 | J7: =J6+J42 | ... P7: =P6+P42 | R7: =((L7/I7)^(1/3))-1 | S7: =((L7/G7)^(1/5))-1 | T7: =IF(C7>0,((L7/C7)^(1/9))-1,"-")
R8: =(TODAY()-I3)/365 | S8: =(TODAY()-G3)/365 | T8: =(TODAY()-C3)/365
A9: Revenue | B9: Cr | C9: ='Data Sheet'!B17 | D9: ='Data Sheet'!C17 | E9: ='Data Sheet'!D17 | F9: ='Data Sheet'!E17 | G9: ='Data Sheet'!F17 | H9: ='Data Sheet'!G17 | I9: ='Data Sheet'!H17 | J9: ='Data Sheet'!I17 | ... L9: ='Data Sheet'!K17 | M9: =L9*(1+$U9) | N9: =M9*(1+$V9) | O9: =N9*(1+$W9) | P9: =SUM(I99:L99) | Q9: =((O9/L9)^(1/3))-1 | R9: =((L9/I9)^(1/3))-1 | S9: =((L9/G9)^(1/5))-1 | T9: =IF(C9>0,((L9/C9)^(1/9))-1,"-") | U9: =R9 | V9: =U9 | W9: =V9
A10: Growth (YoY) | D10: =D9/C9-1 | E10: =E9/D9-1 | F10: =F9/E9-1 | G10: =G9/F9-1 | H10: =H9/G9-1 | I10: =I9/H9-1 | J10: =J9/I9-1 | K10: =K9/J9-1 | ... O10: =O9/N9-1
A11: Gross Profits | B11: Cr | C11: =C9-SUM('Data Sheet'!B18,-1*'Data Sheet'!B19) | D11: =D9-SUM('Data Sheet'!C18,-1*'Data Sheet'!C19) | E11: =E9-SUM('Data Sheet'!D18,-1*'Data Sheet'!D19) | F11: =F9-SUM('Data Sheet'!E18,-1*'Data Sheet'!E19) | G11: =G9-SUM('Data Sheet'!F18,-1*'Data Sheet'!F19) | H11: =H9-SUM('Data Sheet'!G18,-1*'Data Sheet'!G19) | I11: =I9-SUM('Data Sheet'!H18,-1*'Data Sheet'!H19) | J11: =J9-SUM('Data Sheet'!I18,-1*'Data Sheet'!I19) | ... L11: =L9-SUM('Data Sheet'!K18,-1*'Data Sheet'!K19)
A12: Growth (YoY) | D12: =D11/C11-1 | E12: =E11/D11-1 | F12: =F11/E11-1 | H12: =H11/G11-1 | I12: =I11/H11-1 | J12: =J11/I11-1 | K12: =K11/J11-1 | L12: =L11/K11-1
A13: EBITDA | B13: Cr | C13: =C9-SUM('Data Sheet'!B18,'Data Sheet'!B20:B24,-1*'Data Sheet'!B19) | D13: =D9-SUM('Data Sheet'!C18,'Data Sheet'!C20:C24,-1*'Data Sheet'!C19) | E13: =E9-SUM('Data Sheet'!D18,'Data Sheet'!D20:D24,-1*'Data Sheet'!D19) | F13: =F9-SUM('Data Sheet'!E18,'Data Sheet'!E20:E24,-1*'Data Sheet'!E19) | G13: =G9-SUM('Data Sheet'!F18,'Data Sheet'!F20:F24,-1*'Data Sheet'!F19) | H13: =H9-SUM('Data Sheet'!G18,'Data Sheet'!G20:G24,-1*'Data Sheet'!G19) | I13: =I9-SUM('Data Sheet'!H18,'Data Sheet'!H20:H24,-1*'Data Sheet'!H19) | J13: =J9-SUM('Data Sheet'!I18,'Data Sheet'!I20:I24,-1*'Data Sheet'!I19) | ... L13: =L9-SUM('Data Sheet'!K18,'Data Sheet'!K20:K24,-1*'Data Sheet'!K19) | M13: =M9*$U27 | N13: =N9*$V27 | O13: =O9*$W27 | P13: =SUM(I101:L101) | Q13: =((O13/L13)^(1/3))-1 | R13: =((L13/I13)^(1/3))-1 | S13: =((L13/G13)^(1/5))-1 | T13: =IF(C13>0,((L13/C13)^(1/9))-1,"-")
A14: Growth (YoY) | D14: =D13/C13-1 | E14: =E13/D13-1 | F14: =F13/E13-1 | G14: =G13/F13-1 | H14: =H13/G13-1 | I14: =I13/H13-1 | J14: =J13/I13-1 | K14: =K13/J13-1 | ... O14: =O13/N13-1
A15: Other Income | B15: Cr | C15: ='Data Sheet'!B25 | D15: ='Data Sheet'!C25 | E15: ='Data Sheet'!D25 | F15: ='Data Sheet'!E25 | G15: ='Data Sheet'!F25 | H15: ='Data Sheet'!G25 | I15: ='Data Sheet'!H25 | J15: ='Data Sheet'!I25 | ... L15: ='Data Sheet'!K25 | M15: =AVERAGE(J15:L15) | N15: =AVERAGE(K15:M15) | O15: =AVERAGE(L15:N15) | P15: =SUM(I114:L114)
A16: Depreciation | B16: Cr | C16: ='Data Sheet'!B26 | D16: ='Data Sheet'!C26 | E16: ='Data Sheet'!D26 | F16: ='Data Sheet'!E26 | G16: ='Data Sheet'!F26 | H16: ='Data Sheet'!G26 | I16: ='Data Sheet'!H26 | J16: ='Data Sheet'!I26 | ... L16: ='Data Sheet'!K26 | M16: =L16*(1+$U16) | N16: =M16*(1+$V16) | O16: =N16*(1+$W16) | P16: =SUM(I115:L115) | U16: =R45 | V16: =U16 | W16: =V16
A17: Interest | B17: Cr | C17: ='Data Sheet'!B27 | D17: ='Data Sheet'!C27 | E17: ='Data Sheet'!D27 | F17: ='Data Sheet'!E27 | G17: ='Data Sheet'!F27 | H17: ='Data Sheet'!G27 | I17: ='Data Sheet'!H27 | J17: ='Data Sheet'!I27 | ... L17: ='Data Sheet'!K27 | M17: =L17*(1+$U17) | N17: =M17*(1+$V17) | O17: =N17*(1+$W17) | P17: =SUM(I116:L116) | U17: 0.1 | V17: =U17 | W17: =V17
A18: PBT | B18: Cr | C18: ='Data Sheet'!B28 | D18: ='Data Sheet'!C28 | E18: ='Data Sheet'!D28 | F18: ='Data Sheet'!E28 | G18: ='Data Sheet'!F28 | H18: ='Data Sheet'!G28 | I18: ='Data Sheet'!H28 | J18: ='Data Sheet'!I28 | ... L18: ='Data Sheet'!K28 | M18: =M13+M15-M16-M17 | N18: =N13+N15-N16-N17 | O18: =O13+O15-O16-O17 | P18: =P13+P15-P16-P17
A19: Tax | B19: Cr | C19: ='Data Sheet'!B29 | D19: ='Data Sheet'!C29 | E19: ='Data Sheet'!D29 | F19: ='Data Sheet'!E29 | G19: ='Data Sheet'!F29 | H19: ='Data Sheet'!G29 | I19: ='Data Sheet'!H29 | J19: ='Data Sheet'!I29 | ... L19: ='Data Sheet'!K29 | M19: =M18*$U30 | N19: =N18*$V30 | O19: =O18*$W30 | P19: =P18-P20
A20: PAT | B20: Cr | C20: ='Data Sheet'!B30 | D20: ='Data Sheet'!C30 | E20: ='Data Sheet'!D30 | F20: ='Data Sheet'!E30 | G20: ='Data Sheet'!F30 | H20: ='Data Sheet'!G30 | I20: ='Data Sheet'!H30 | J20: ='Data Sheet'!I30 | ... L20: ='Data Sheet'!K30 | M20: =M18-M19 | N20: =N18-N19 | O20: =O18-O19 | P20: =SUM(I105:L105) | Q20: =((O20/L20)^(1/3))-1 | R20: =((L20/I20)^(1/3))-1 | S20: =((L20/G20)^(1/5))-1 | T20: =IF(C20>0,((L20/C20)^(1/9))-1,"-")
A21: Growth (YoY) | D21: =D20/C20-1 | E21: =E20/D20-1 | F21: =F20/E20-1 | G21: =G20/F20-1 | H21: =H20/G20-1 | I21: =I20/H20-1 | J21: =J20/I20-1 | K21: =K20/J20-1 | ... O21: =O20/N20-1
A22: EPS | B22: INR | C22: =C20/C5 | D22: =D20/D5 | E22: =E20/E5 | F22: =F20/F5 | G22: =G20/G5 | H22: =H20/H5 | I22: =I20/I5 | J22: =J20/J5 | ... P22: =P20/P5 | R22: =((L22/I22)^(1/3))-1 | S22: =((L22/G22)^(1/5))-1 | T22: =IF(C22>0,((L22/C22)^(1/9))-1,"-")
A23: DPS | B23: INR | C23: ='Data Sheet'!B31/C5 | D23: ='Data Sheet'!C31/D5 | E23: ='Data Sheet'!D31/E5 | F23: ='Data Sheet'!E31/F5 | G23: ='Data Sheet'!F31/G5 | H23: ='Data Sheet'!G31/H5 | I23: ='Data Sheet'!H31/I5 | J23: ='Data Sheet'!I31/J5 | ... L23: ='Data Sheet'!K31/L5 | M23: =M22*$U32 | N23: =N22*$V32 | O23: =O22*$W32 | R23: =((L23/I23)^(1/3))-1 | S23: =((L23/G23)^(1/5))-1 | T23: =IF(C23>0,((L23/C23)^(1/9))-1,"-")
A25: RATIOS
A26: GPM | B26: % | C26: =C11/C$9 | D26: =D11/D$9 | E26: =E11/E$9 | F26: =F11/F$9 | G26: =G11/G$9 | H26: =H11/H$9 | I26: =I11/I$9 | J26: =J11/J$9 | ... L26: =L11/L$9 | R26: =AVERAGE(J26:L26) | S26: =AVERAGE(H26:L26) | T26: =AVERAGE(C26:L26)
A27: EBITDAM | B27: % | C27: =C13/C$9 | D27: =D13/D$9 | E27: =E13/E$9 | F27: =F13/F$9 | G27: =G13/G$9 | H27: =H13/H$9 | I27: =I13/I$9 | J27: =J13/J$9 | ... P27: =P13/P$9 | R27: =AVERAGE(J27:L27) | S27: =AVERAGE(H27:L27) | T27: =AVERAGE(C27:L27) | U27: =R27 | V27: =U27 | W27: =V27
A28: Depn / Net Assets | B28: % | C28: =C16/(C45+C46) | D28: =D16/(D45+D46) | E28: =E16/(E45+E46) | F28: =F16/(F45+F46) | G28: =G16/(G45+G46) | H28: =H16/(H45+H46) | I28: =I16/(I45+I46) | J28: =J16/(J45+J46) | ... O28: =O16/(O45+O46) | Q28: =AVERAGE(M28:O28) | R28: =AVERAGE(J28:L28) | S28: =AVERAGE(H28:L28) | T28: =AVERAGE(C28:L28)
A29: Interest /Total Debt | B29: % | C29: =C17/C42 | D29: =D17/D42 | E29: =E17/E42 | F29: =F17/F42 | G29: =G17/G42 | H29: =H17/H42 | I29: =I17/I42 | J29: =J17/J42 | ... O29: =O17/O42 | Q29: =AVERAGE(M29:O29) | R29: =AVERAGE(J29:L29) | S29: =AVERAGE(H29:L29) | T29: =AVERAGE(C29:L29)
A30: Tax Rate | B30: % | C30: =C19/C18 | D30: =D19/D18 | E30: =E19/E18 | F30: =F19/F18 | G30: =G19/G18 | H30: =H19/H18 | I30: =I19/I18 | J30: =J19/J18 | ... P30: =P19/P18 | Q30: =AVERAGE(M30:O30) | R30: =AVERAGE(J30:L30) | S30: =AVERAGE(H30:L30) | T30: =AVERAGE(C30:L30) | U30: =R30 | V30: =U30 | W30: =V30
A31: PAT Margins | B31: % | C31: =C20/C$9 | D31: =D20/D$9 | E31: =E20/E$9 | F31: =F20/F$9 | G31: =G20/G$9 | H31: =H20/H$9 | I31: =I20/I$9 | J31: =J20/J$9 | ... P31: =P20/P$9 | R31: =AVERAGE(J31:L31) | S31: =AVERAGE(H31:L31) | T31: =AVERAGE(C31:L31)
A32: Payout Ratio | B32: % | C32: =C23/C22 | D32: =D23/D22 | E32: =E23/E22 | F32: =F23/F22 | G32: =G23/G22 | H32: =H23/H22 | I32: =I23/I22 | J32: =J23/J22 | ... O32: =O23/O22 | R32: =AVERAGE(J32:L32) | S32: =AVERAGE(H32:L32) | T32: =AVERAGE(C32:L32) | U32: =R32 | V32: =U32 | W32: =V32
A34: Growth - YoY
A35: =A9 | B35: % | D35: =D9/C9-1 | E35: =E9/D9-1 | F35: =F9/E9-1 | G35: =G9/F9-1 | H35: =H9/G9-1 | I35: =I9/H9-1 | J35: =J9/I9-1 | K35: =K9/J9-1 | ... O35: =O9/N9-1 | P35: =P9/L9-1
A36: GP growth | B36: % | D36: =D11/C11-1 | E36: =E11/D11-1 | F36: =F11/E11-1 | G36: =G11/F11-1 | H36: =H11/G11-1 | I36: =I11/H11-1 | J36: =J11/I11-1 | K36: =K11/J11-1 | L36: =L11/K11-1
A37: EBITDA | B37: % | D37: =D13/C13-1 | E37: =E13/D13-1 | F37: =F13/E13-1 | G37: =G13/F13-1 | H37: =H13/G13-1 | I37: =I13/H13-1 | J37: =J13/I13-1 | K37: =K13/J13-1 | ... O37: =O13/N13-1 | P37: =P13/L13-1
A38: PAT | B38: % | D38: =D20/C20-1 | E38: =E20/D20-1 | F38: =F20/E20-1 | G38: =G20/F20-1 | H38: =H20/G20-1 | I38: =I20/H20-1 | J38: =J20/I20-1 | K38: =K20/J20-1 | ... O38: =O20/N20-1 | P38: =P20/L20-1
A40: BALANCE SHEET
A41: Networth | B41: Cr | C41: ='Data Sheet'!B57+'Data Sheet'!B58 | D41: ='Data Sheet'!C57+'Data Sheet'!C58 | E41: ='Data Sheet'!D57+'Data Sheet'!D58 | F41: ='Data Sheet'!E57+'Data Sheet'!E58 | G41: ='Data Sheet'!F57+'Data Sheet'!F58 | H41: ='Data Sheet'!G57+'Data Sheet'!G58 | I41: ='Data Sheet'!H57+'Data Sheet'!H58 | J41: ='Data Sheet'!I57+'Data Sheet'!I58 | ... L41: ='Data Sheet'!K57+'Data Sheet'!K58 | M41: =L41+M20-M5*M23 | N41: =M41+N20-N5*N23 | O41: =N41+O20-O5*O23 | Q41: =((O41/L41)^(1/3))-1 | R41: =((L41/I41)^(1/3))-1 | S41: =((L41/G41)^(1/5))-1 | T41: =IF(C41>0,((L41/C41)^(1/9))-1,"-")
A42: Total Debt | B42: Cr | C42: ='Data Sheet'!B59 | D42: ='Data Sheet'!C59 | E42: ='Data Sheet'!D59 | F42: ='Data Sheet'!E59 | G42: ='Data Sheet'!F59 | H42: ='Data Sheet'!G59 | I42: ='Data Sheet'!H59 | J42: ='Data Sheet'!I59 | ... L42: ='Data Sheet'!K59 | M42: =(M45+M46+M47+M50)-M41 | N42: =(N45+N46+N47+N50)-N41 | O42: =(O45+O46+O47+O50)-O41 | P42: =L42 | Q42: =((O42/L42)^(1/3))-1 | R42: =((L42/I42)^(1/3))-1 | S42: =((L42/G42)^(1/5))-1 | T42: =IF(C42>0,((L42/C42)^(1/9))-1,"-")
A43: CAPITAL EMPLOYED | B43: Cr | C43: =SUM(C41:C42) | D43: =SUM(D41:D42) | E43: =SUM(E41:E42) | F43: =SUM(F41:F42) | G43: =SUM(G41:G42) | H43: =SUM(H41:H42) | I43: =SUM(I41:I42) | J43: =SUM(J41:J42) | ... O43: =SUM(O41:O42) | Q43: =((O43/L43)^(1/3))-1 | R43: =((L43/I43)^(1/3))-1 | S43: =((L43/G43)^(1/5))-1 | T43: =IF(C43>0,((L43/C43)^(1/9))-1,"-")
...

Sheet Segments
D1: ='Data Sheet'!B16 | E1: ='Data Sheet'!C16 | F1: ='Data Sheet'!D16 | G1: ='Data Sheet'!E16 | H1: ='Data Sheet'!F16 | I1: ='Data Sheet'!G16 | J1: ='Data Sheet'!H16 | K1: ='Data Sheet'!I16 | ... M1: ='Data Sheet'!K16 | N1: =M1+365 | O1: =N1+365 | P1: =O1+365 | Q1: TTM | R1: 3 Yr Proj CAGR | S1: 3 Yr CAGR | T1: 5 Yr CAGR | U1: 9Yr CAGR | V1: =N1 | W1: =O1 | X1: =P1
A2: Revenue | B2: Cr | D2: ='Data Sheet'!B17 | E2: ='Data Sheet'!C17 | F2: ='Data Sheet'!D17 | G2: ='Data Sheet'!E17 | H2: ='Data Sheet'!F17 | I2: ='Data Sheet'!G17 | J2: ='Data Sheet'!H17 | K2: ='Data Sheet'!I17 | ... M2: ='Data Sheet'!K17 | N2: =M2*(1+$V2) | O2: =N2*(1+$W2) | P2: =O2*(1+$X2) | Q2: =SUM(J53:M53) | R2: =((P2/M2)^(1/3))-1 | S2: =((M2/J2)^(1/3))-1 | T2: =((M2/H2)^(1/5))-1 | U2: =IF(D2>0,((M2/D2)^(1/9))-1,"-") | V2: =S2 | W2: =V2 | X2: =W2
A3: PBIT | B3: Cr | D3: ='Data Sheet'!B28+'Data Sheet'!B27 | E3: ='Data Sheet'!C28+'Data Sheet'!C27 | F3: ='Data Sheet'!D28+'Data Sheet'!D27 | G3: ='Data Sheet'!E28+'Data Sheet'!E27 | H3: ='Data Sheet'!F28+'Data Sheet'!F27 | I3: ='Data Sheet'!G28+'Data Sheet'!G27 | J3: ='Data Sheet'!H28+'Data Sheet'!H27 | K3: ='Data Sheet'!I28+'Data Sheet'!I27 | ... M3: ='Data Sheet'!K28+'Data Sheet'!K27 | N3: =Financial!M18+Financial!M17 | O3: =Financial!N18+Financial!N17 | P3: =Financial!O18+Financial!O17 | Q3: =SUM('Data Sheet'!H47:K47)+SUM('Data Sheet'!H46:K46)
A4: CAPITAL EMPLOYED | D4: =Financial!C43 | E4: =Financial!D43 | F4: =Financial!E43 | G4: =Financial!F43 | H4: =Financial!G43 | I4: =Financial!H43 | J4: =Financial!I43 | K4: =Financial!J43 | ... P4: =Financial!O43
A5: DEVIATION
A6: Revenue | D6: =D2/D20-1 | E6: =E2/E20-1 | F6: =F2/F20-1 | G6: =G2/G20-1 | H6: =H2/H20-1 | I6: =I2/I20-1 | J6: =J2/J20-1 | K6: =K2/K20-1 | ... P6: =P2/P20-1
A7: PBIT | D7: =D3/D32-1 | E7: =E3/E32-1 | F7: =F3/F32-1 | G7: =G3/G32-1 | H7: =H3/H32-1 | I7: =I3/I32-1 | J7: =J3/J32-1 | K7: =K3/K32-1 | ... M7: =M3/M32-1
A8: CAPITAL EMPLOYED
A10: SEGMENT REVENUE | D10: =D1 | E10: =E1 | F10: =F1 | G10: =G1 | H10: =H1 | I10: =I1 | J10: =J1 | K10: =K1 | ... P10: =P1
A11: Banking Finance Insurance | B11: 21062 | C11: 27146 | D11: 35112 | E11: 38566 | F11: 44163 | G11: 47505 | H11: 48418 | I11: 57938 | J11: 61095 | K11: 65634 | L11: 75126 | M11: 86127 | N11: =M11*(1+$V11) | O11: =N11*(1+$W11) | P11: =O11*(1+$X11) | R11: =((P11/M11)^(1/3))-1 | S11: =((M11/J11)^(1/3))-1 | T11: =((M11/H11)^(1/5))-1 | U11: =IF(D11>0,((M11/D11)^(1/9))-1,"-") | V11: =S11 | W11: =V11 | X11: =W11
A12: Communication, Media and Technology | B12: 6205 | C12: 7540 | D12: 9614 | E12: 10934 | F12: 18040 | G12: 19521 | H12: 21131 | I12: 23925 | J12: 25978 | K12: 27077 | L12: 31874 | M12: 37653 | N12: =M12*(1+$V12) | O12: =N12*(1+$W12) | P12: =O12*(1+$X12) | R12: =((P12/M12)^(1/3))-1 | S12: =((M12/J12)^(1/3))-1 | T12: =((M12/H12)^(1/5))-1 | U12: =IF(D12>0,((M12/D12)^(1/9))-1,"-") | V12: =S12 | W12: =V12 | X12: =W12
A13: Retail and Consumer Packing Goods | B13: 5954 | C13: 8401 | D13: 11309 | E13: 12829 | F13: 19204 | G13: 20459 | H13: 21055 | I13: 25164 | J13: 26280 | K13: 25589 | L13: 30715 | M13: 37506 | N13: =M13*(1+$V13) | O13: =N13*(1+$W13) | P13: =O13*(1+$X13) | R13: =((P13/M13)^(1/3))-1 | S13: =((M13/J13)^(1/3))-1 | T13: =((M13/H13)^(1/5))-1 | U13: =IF(D13>0,((M13/D13)^(1/9))-1,"-") | V13: =S13 | W13: =V13 | X13: =W13
A14: Life Sciences and Healthcare | B14: 0 | C14: 0 | D14: 0 | E14: 0 | F14: 0 | G14: 0 | H14: 0 | I14: 0 | J14: 0 | K14: 16968 | L14: 20462 | M14: 24605 | N14: =M14*(1+$V14) | O14: =N14*(1+$W14) | P14: =O14*(1+$X14) | R14: =((P14/M14)^(1/3))-1 | S14: =((M14/J14)^(1/3))-1 | T14: =((M14/H14)^(1/5))-1 | U14: =IF(D14>0,((M14/D14)^(1/9))-1,"-") | V14: =S14 | W14: =V14 | X14: =W14
A15: Manufacturing | B15: 3801 | C15: 5216 | D15: 6989 | E15: 9242 | F15: 10909 | G15: 12486 | H15: 13361 | I15: 15682 | J15: 16468 | K15: 15950 | L15: 18610 | M15: 21236 | N15: =M15*(1+$V15) | O15: =N15*(1+$W15) | P15: =O15*(1+$X15) | R15: =((P15/M15)^(1/3))-1 | S15: =((M15/J15)^(1/3))-1 | T15: =((M15/H15)^(1/5))-1 | U15: =IF(D15>0,((M15/D15)^(1/9))-1,"-") | V15: =S15 | W15: =V15 | X15: =W15
A16: Others | B16: 11872 | C16: 14687 | D16: 18785 | E16: 23078 | F16: 16330 | G16: 17995 | H16: 19139 | I16: 23754 | J16: 27128 | K16: 12959 | L16: 14967 | M16: 18331 | N16: =M16*(1+$V16) | O16: =N16*(1+$W16) | P16: =O16*(1+$X16) | R16: =((P16/M16)^(1/3))-1 | S16: =((M16/J16)^(1/3))-1 | T16: =((M16/H16)^(1/5))-1 | U16: =IF(D16>0,((M16/D16)^(1/9))-1,"-") | V16: =S16 | W16: =V16 | X16: =W16
N17: =M17*(1+$V17) | O17: =N17*(1+$W17) | P17: =O17*(1+$X17) | R17: =((P17/M17)^(1/3))-1 | S17: =((M17/J17)^(1/3))-1 | T17: =((M17/H17)^(1/5))-1 | U17: =IF(D17>0,((M17/D17)^(1/9))-1,"-") | V17: =S17 | W17: =V17 | X17: =W17
N18: =M18*(1+$V18) | O18: =N18*(1+$W18) | P18: =O18*(1+$X18) | R18: =((P18/M18)^(1/3))-1 | S18: =((M18/J18)^(1/3))-1 | T18: =((M18/H18)^(1/5))-1 | U18: =IF(D18>0,((M18/D18)^(1/9))-1,"-") | V18: =S18 | W18: =V18 | X18: =W18
A19: Pledge | N19: =M19*(1+$V19) | O19: =N19*(1+$W19) | P19: =O19*(1+$X19) | R19: =((P19/M19)^(1/3))-1 | S19: =((M19/J19)^(1/3))-1 | T19: =((M19/H19)^(1/5))-1 | U19: =IF(D19>0,((M19/D19)^(1/9))-1,"-") | V19: =S19 | W19: =V19 | X19: =W19
A20: TOTAL | D20: =SUM(D11:D19) | E20: =SUM(E11:E19) | F20: =SUM(F11:F19) | G20: =SUM(G11:G19) | H20: =SUM(H11:H19) | I20: =SUM(I11:I19) | J20: =SUM(J11:J19) | K20: =SUM(K11:K19) | ... P20: =SUM(P11:P19) | R20: =((P20/M20)^(1/3))-1 | S20: =((M20/J20)^(1/3))-1 | T20: =((M20/H20)^(1/5))-1 | U20: =IF(D20>0,((M20/D20)^(1/9))-1,"-") | V20: =S20 | W20: =V20 | X20: =W20
A21: Managerial Remuneration | B21: Cr | R21: =((P21/M21)^(1/3))-1 | S21: =((M21/J21)^(1/3))-1 | T21: =((M21/H21)^(1/5))-1 | U21: =IF(D21>0,((M21/D21)^(1/9))-1,"-") | V21: =S21 | W21: =V21 | X21: =W21
A22: SEGMENT PBIT | R22: =((P22/M22)^(1/3))-1 | S22: =((M22/J22)^(1/3))-1 | T22: =((M22/H22)^(1/5))-1 | U22: =IF(D22>0,((M22/D22)^(1/9))-1,"-") | V22: =S22 | W22: =V22 | X22: =W22
A23: Banking Finance Insurance | B23: 6493 | C23: 8014 | D23: 11523 | E23: 10594 | F23: 12851 | G23: 13098 | H23: 13045 | I23: 16089 | J23: 16950 | K23: 18681 | L23: 20174 | M23: 22345 | N23: =M23*(1+$V23) | O23: =N23*(1+$W23) | P23: =O23*(1+$X23) | R23: =((P23/M23)^(1/3))-1 | S23: =((M23/J23)^(1/3))-1 | T23: =((M23/H23)^(1/5))-1 | U23: =IF(D23>0,((M23/D23)^(1/9))-1,"-") | V23: =S23 | W23: =V23 | X23: =W23
A24: Communication, Media and Technology | B24: 1890 | C24: 1949 | D24: 2749 | E24: 2771 | F24: 5190 | G24: 5552 | H24: 5797 | I24: 6644 | J24: 7703 | K24: 8010 | L24: 9518 | M24: 10667 | N24: =M24*(1+$V24) | O24: =N24*(1+$W24) | P24: =O24*(1+$X24) | R24: =((P24/M24)^(1/3))-1 | S24: =((M24/J24)^(1/3))-1 | T24: =((M24/H24)^(1/5))-1 | U24: =IF(D24>0,((M24/D24)^(1/9))-1,"-") | V24: =S24 | W24: =V24 | X24: =W24
A25: Retail and Consumer Packing Goods | B25: 1742 | C25: 2581 | D25: 3674 | E25: 3254 | F25: 5330 | G25: 5740 | H25: 5580 | I25: 6871 | J25: 6870 | K25: 7151 | L25: 8534 | M25: 9636 | N25: =M25*(1+$V25) | O25: =N25*(1+$W25) | P25: =O25*(1+$X25) | R25: =((P25/M25)^(1/3))-1 | S25: =((M25/J25)^(1/3))-1 | T25: =((M25/H25)^(1/5))-1 | U25: =IF(D25>0,((M25/D25)^(1/9))-1,"-") | V25: =S25 | W25: =V25 | X25: =W25
A26: Life Sciences and Healthcare | B26: 0 | C26: 0 | D26: 0 | E26: 0 | F26: 0 | G26: 0 | H26: 0 | I26: 0 | J26: 0 | K26: 5253 | L26: 6139 | M26: 6894 | N26: =M26*(1+$V26) | O26: =N26*(1+$W26) | P26: =O26*(1+$X26) | R26: =((P26/M26)^(1/3))-1 | S26: =((M26/J26)^(1/3))-1 | T26: =((M26/H26)^(1/5))-1 | U26: =IF(D26>0,((M26/D26)^(1/9))-1,"-") | V26: =S26 | W26: =V26 | X26: =W26
A27: Manufacturing | B27: 986 | C27: 1363 | D27: 2051 | E27: 2223 | F27: 2924 | G27: 3574 | H27: 3698 | I27: 4311 | J27: 4445 | K27: 4483 | L27: 5602 | M27: 5842 | N27: =M27*(1+$V27) | O27: =N27*(1+$W27) | P27: =O27*(1+$X27) | R27: =((P27/M27)^(1/3))-1 | S27: =((M27/J27)^(1/3))-1 | T27: =((M27/H27)^(1/5))-1 | U27: =IF(D27>0,((M27/D27)^(1/9))-1,"-") | V27: =S27 | W27: =V27 | X27: =W27
A28: Others | B28: 3203 | C28: 3992 | D28: 5029 | E28: 5480 | F28: 4294 | G28: 4271 | H28: 4339 | I28: 5554 | J28: 6141 | K28: 2968 | L28: 3090 | M28: 3875 | N28: =M28*(1+$V28) | O28: =N28*(1+$W28) | P28: =O28*(1+$X28) | R28: =((P28/M28)^(1/3))-1 | S28: =((M28/J28)^(1/3))-1 | T28: =((M28/H28)^(1/5))-1 | U28: =IF(D28>0,((M28/D28)^(1/9))-1,"-") | V28: =S28 | W28: =V28 | X28: =W28
A29: Unallocated | B29: -390 | C29: 192 | D29: 377 | E29: 1486 | F29: 1251 | G29: 2278 | H29: 1633 | I29: 2094 | J29: 139 | K29: -2786 | L29: -1370 | M29: -2352 | N29: =M29*(1+$V29) | O29: =N29*(1+$W29) | P29: =O29*(1+$X29) | R29: =((P29/M29)^(1/3))-1 | S29: =((M29/J29)^(1/3))-1 | T29: =((M29/H29)^(1/5))-1 | U29: =IF(D29>0,((M29/D29)^(1/9))-1,"-") | V29: =S29 | W29: =V29 | X29: =W29
N30: =M30*(1+$V30) | O30: =N30*(1+$W30) | P30: =O30*(1+$X30) | R30: =((P30/M30)^(1/3))-1 | S30: =((M30/J30)^(1/3))-1 | T30: =((M30/H30)^(1/5))-1 | U30: =IF(D30>0,((M30/D30)^(1/9))-1,"-") | V30: =S30 | W30: =V30 | X30: =W30
A31: Pledge | N31: =M31*(1+$V31) | O31: =N31*(1+$W31) | P31: =O31*(1+$X31) | R31: =((P31/M31)^(1/3))-1 | S31: =((M31/J31)^(1/3))-1 | T31: =((M31/H31)^(1/5))-1 | U31: =IF(D31>0,((M31/D31)^(1/9))-1,"-") | V31: =S31 | W31: =V31 | X31: =W31
A32: TOTAL | B32: =SUM(B23:B31) | C32: =SUM(C23:C31) | D32: =SUM(D23:D31) | E32: =SUM(E23:E31) | F32: =SUM(F23:F31) | G32: =SUM(G23:G31) | H32: =SUM(H23:H31) | I32: =SUM(I23:I31) | ... P32: =SUM(P23:P31) | R32: =((P32/M32)^(1/3))-1 | S32: =((M32/J32)^(1/3))-1 | T32: =((M32/H32)^(1/5))-1 | U32: =IF(D32>0,((M32/D32)^(1/9))-1,"-") | V32: =S32 | W32: =V32 | X32: =W32
R33: =((P33/M33)^(1/3))-1 | S33: =((M33/J33)^(1/3))-1 | T33: =((M33/H33)^(1/5))-1 | U33: =IF(D33>0,((M33/D33)^(1/9))-1,"-") | V33: =S33 | W33: =V33 | X33: =W33
A34: SEGMENT CAPITAL EMPLOYED | R34: =((P34/M34)^(1/3))-1 | S34: =((M34/J34)^(1/3))-1 | T34: =((M34/H34)^(1/5))-1 | U34: =IF(D34>0,((M34/D34)^(1/9))-1,"-") | V34: =S34 | W34: =V34 | X34: =W34
A35: Banking Finance Insurance | B35: 8570 | C35: 10045 | D35: 8344 | E35: 7057 | F35: 9681 | G35: 8635 | H35: 9039 | I35: 10483 | J35: 0 | K35: 0 | L35: 0 | M35: 0 | R35: =((P35/M35)^(1/3))-1 | S35: =((M35/J35)^(1/3))-1 | T35: =((M35/H35)^(1/5))-1 | U35: =IF(D35>0,((M35/D35)^(1/9))-1,"-") | V35: =S35 | W35: =V35 | X35: =W35
A36: Communication, Media and Technology | B36: 1901 | C36: 2336 | D36: 2977 | E36: 2697 | F36: 4639 | G36: 4671 | H36: 5605 | I36: 5590 | J36: 0 | K36: 0 | L36: 0 | M36: 0 | R36: =((P36/M36)^(1/3))-1 | S36: =((M36/J36)^(1/3))-1 | T36: =((M36/H36)^(1/5))-1 | U36: =IF(D36>0,((M36/D36)^(1/9))-1,"-") | V36: =S36 | W36: =V36 | X36: =W36
A37: Retail and Consumer Packing Goods | B37: 1384 | C37: 2051 | D37: 2924 | E37: 2768 | F37: 4641 | G37: 4850 | H37: 5546 | I37: 0 | J37: 0 | K37: 0 | L37: 0 | M37: 0 | R37: =((P37/M37)^(1/3))-1 | S37: =((M37/J37)^(1/3))-1 | T37: =((M37/H37)^(1/5))-1 | U37: =IF(D37>0,((M37/D37)^(1/9))-1,"-") | V37: =S37 | W37: =V37 | X37: =W37
A38: Manufacturing | B38: 991 | C38: 1493 | D38: 1994 | E38: 2148 | F38: 2676 | G38: 3100 | H38: 3381 | I38: 4043 | J38: 0 | K38: 0 | L38: 0 | M38: 0 | R38: =((P38/M38)^(1/3))-1 | S38: =((M38/J38)^(1/3))-1 | T38: =((M38/H38)^(1/5))-1 | U38: =IF(D38>0,((M38/D38)^(1/9))-1,"-") | V38: =S38 | W38: =V38 | X38: =W38
A39: Others | B39: 5179 | C39: 6027 | D39: 7009 | E39: 7121 | F39: 5531 | G39: 5569 | H39: 6223 | I39: 6864 | J39: 0 | K39: 0 | L39: 0 | M39: 0 | R39: =((P39/M39)^(1/3))-1 | S39: =((M39/J39)^(1/3))-1 | T39: =((M39/H39)^(1/5))-1 | U39: =IF(D39>0,((M39/D39)^(1/9))-1,"-") | V39: =S39 | W39: =V39 | X39: =W39
A40: Retail and Distribution | B40: 0 | C40: 0 | D40: 0 | E40: 0 | F40: 0 | G40: 0 | H40: 0 | I40: 6447 | J40: 0 | K40: 0 | L40: 0 | M40: 0 | R40: =((P40/M40)^(1/3))-1 | S40: =((M40/J40)^(1/3))-1 | T40: =((M40/H40)^(1/5))-1 | U40: =IF(D40>0,((M40/D40)^(1/9))-1,"-") | V40: =S40 | W40: =V40 | X40: =W40
A41: Unallocated | B41: 12112 | C41: 17389 | D41: 26655 | E41: 29971 | F41: 44259 | G41: 59755 | H41: 55736 | I41: 56472 | J41: 0 | K41: 0 | L41: 0 | M41: 0 | R41: =((P41/M41)^(1/3))-1 | S41: =((M41/J41)^(1/3))-1 | T41: =((M41/H41)^(1/5))-1 | U41: =IF(D41>0,((M41/D41)^(1/9))-1,"-") | V41: =S41 | W41: =V41 | X41: =W41
...

Sheet Estimates
B1: ='Data Sheet'!B1 | C1: =VLOOKUP(B1,Lookup!A:C,3,FALSE) | D1: https://goindiastocks.com/GIA/stockDashboard?Fincode= | E1: =CONCATENATE(D1,C1)
C2: =VLOOKUP(B1,Lookup!A:C,2,FALSE)
A3: =[1]Sheet1!A2 | B3: =[1]Sheet1!B2 | C3: =[1]Sheet1!C2 | D3: =[1]Sheet1!D2 | E3: =[1]Sheet1!E2 | F3: =[1]Sheet1!F2 | G3: =[1]Sheet1!G2 | H3: =[1]Sheet1!H2 | ... N3: =[1]Sheet1!N2
A4: =[1]Sheet1!A3 | B4: =[1]Sheet1!B3 | C4: =[1]Sheet1!C3 | D4: =[1]Sheet1!D3 | E4: =[1]Sheet1!E3 | F4: =[1]Sheet1!F3 | G4: =[1]Sheet1!G3 | H4: =[1]Sheet1!H3 | ... N4: =[1]Sheet1!N3
A5: =[1]Sheet1!A4 | B5: =[1]Sheet1!B4 | C5: =[1]Sheet1!C4 | D5: =[1]Sheet1!D4 | E5: =[1]Sheet1!E4 | F5: =[1]Sheet1!F4 | G5: =[1]Sheet1!G4 | H5: =[1]Sheet1!H4 | ... N5: =[1]Sheet1!N4
A6: =[1]Sheet1!A5 | B6: =[1]Sheet1!B5 | C6: =[1]Sheet1!C5 | D6: =[1]Sheet1!D5 | E6: =[1]Sheet1!E5 | F6: =[1]Sheet1!F5 | G6: =[1]Sheet1!G5 | H6: =[1]Sheet1!H5 | ... N6: =[1]Sheet1!N5
A7: =[1]Sheet1!A6 | B7: =[1]Sheet1!B6 | C7: =[1]Sheet1!C6 | D7: =[1]Sheet1!D6 | E7: =[1]Sheet1!E6 | F7: =[1]Sheet1!F6 | G7: =[1]Sheet1!G6 | H7: =[1]Sheet1!H6 | ... N7: =[1]Sheet1!N6
A8: =[1]Sheet1!A7 | B8: =[1]Sheet1!B7 | C8: =[1]Sheet1!C7 | D8: =[1]Sheet1!D7 | E8: =[1]Sheet1!E7 | F8: =[1]Sheet1!F7 | G8: =[1]Sheet1!G7 | H8: =[1]Sheet1!H7 | ... N8: =[1]Sheet1!N7
A9: =[1]Sheet1!A8 | B9: =[1]Sheet1!B8 | C9: =[1]Sheet1!C8 | D9: =[1]Sheet1!D8 | E9: =[1]Sheet1!E8 | F9: =[1]Sheet1!F8 | G9: =[1]Sheet1!G8 | H9: =[1]Sheet1!H8 | ... N9: =[1]Sheet1!N8
A10: =[1]Sheet1!A9 | B10: =[1]Sheet1!B9 | C10: =[1]Sheet1!C9 | D10: =[1]Sheet1!D9 | E10: =[1]Sheet1!E9 | F10: =[1]Sheet1!F9 | G10: =[1]Sheet1!G9 | H10: =[1]Sheet1!H9 | ... N10: =[1]Sheet1!N9
A11: =[1]Sheet1!A10 | B11: =[1]Sheet1!B10 | C11: =[1]Sheet1!C10 | D11: =[1]Sheet1!D10 | E11: =[1]Sheet1!E10 | F11: =[1]Sheet1!F10 | G11: =[1]Sheet1!G10 | H11: =[1]Sheet1!H10 | ... N11: =[1]Sheet1!N10
A12: =[1]Sheet1!A11 | B12: =[1]Sheet1!B11 | C12: =[1]Sheet1!C11 | D12: =[1]Sheet1!D11 | E12: =[1]Sheet1!E11 | F12: =[1]Sheet1!F11 | G12: =[1]Sheet1!G11 | H12: =[1]Sheet1!H11 | ... N12: =[1]Sheet1!N11
A13: =[1]Sheet1!A12 | B13: =[1]Sheet1!B12 | C13: =[1]Sheet1!C12 | D13: =[1]Sheet1!D12 | E13: =[1]Sheet1!E12 | F13: =[1]Sheet1!F12 | G13: =[1]Sheet1!G12 | H13: =[1]Sheet1!H12 | ... N13: =[1]Sheet1!N12
A14: =[1]Sheet1!A13 | B14: =[1]Sheet1!B13 | C14: =[1]Sheet1!C13 | D14: =[1]Sheet1!D13 | E14: =[1]Sheet1!E13 | F14: =[1]Sheet1!F13 | G14: =[1]Sheet1!G13 | H14: =[1]Sheet1!H13 | ... N14: =[1]Sheet1!N13
... A18: =[1]Sheet1!A17 | B18: =[1]Sheet1!B17 | C18: =[1]Sheet1!C17 | D18: =[1]Sheet1!D17 | E18: =[1]Sheet1!E17 | F18: =[1]Sheet1!F17 | G18: =[1]Sheet1!G17 | H18: =[1]Sheet1!H17 | ... N18: =[1]Sheet1!N17
A20: Revenue | B20: =B4/Financial!C9-1 | C20: =C4/Financial!D9-1 | D20: =D4/Financial!E9-1 | E20: =E4/Financial!F9-1 | F20: =F4/Financial!G9-1 | G20: =G4/Financial!H9-1 | H20: =H4/Financial!I9-1 | I20: =I4/Financial!J9-1 | ... N20: =N4/Financial!O9-1
A21: EBITDA | B21: =B6/Financial!C13-1 | C21: =C6/Financial!D13-1 | D21: =D6/Financial!E13-1 | E21: =E6/Financial!F13-1 | F21: =F6/Financial!G13-1 | G21: =G6/Financial!H13-1 | H21: =H6/Financial!I13-1 | I21: =I6/Financial!J13-1 | ... N21: =N6/Financial!O13-1
A22: PAT | B22: =B9/Financial!C20-1 | C22: =C9/Financial!D20-1 | D22: =D9/Financial!E20-1 | E22: =E9/Financial!F20-1 | F22: =F9/Financial!G20-1 | G22: =G9/Financial!H20-1 | H22: =H9/Financial!I20-1 | I22: =I9/Financial!J20-1 | ... N22: =N9/Financial!O20-1
A23: BVPS | B23: =B17/Financial!C86-1 | C23: =C17/Financial!D86-1 | D23: =D17/Financial!E86-1 | E23: =E17/Financial!F86-1 | F23: =F17/Financial!G86-1 | G23: =G17/Financial!H86-1 | H23: =H17/Financial!I86-1 | I23: =I17/Financial!J86-1 | ... N23: =N17/Financial!O86-1

Sheet Customization
A1: How to use it?
A3: You can customize this workbook as you want.
B4: You can add custom formating, add conditional formating, add your own formulas… do ANYTHING.
B5: Please don't edit the "Data Sheet" only.
A7: After customization, you can upload this back on Screener.
B8: Upload on: | C8: https://www.screener.in/excel/
A10: Download your customized workbooks now onwards.
B11: Now whenever you will "Export to excel" from Screener, it will export your customized file.
A14: TESTING:
B15: This is a testing feature currently.
B16: You can report any formula errors on the worksheet at: | G16: screener.feedback@dalal-street.in

Sheet Data Sheet
A1: COMPANY NAME | B1: GRAVITA INDIA LTD | E1: =IF(B2<>B3, "A NEW VERSION OF THE WORKSHEET IS AVAILABLE", "")
A2: LATEST VERSION | B2: 2.1 | E2: PLEASE DO NOT MAKE ANY CHANGES TO THIS SHEET
A3: CURRENT VERSION | B3: 2.1
A5: META
A6: Number of shares | B6: =IF(B9>0, B9/B8, 0)
A7: Face Value | B7: 2
A8: Current Price | B8: 1777
A9: Market Capitalization | B9: 13112.41
A15: PROFIT & LOSS
A16: Report Date | B16: 42825 | C16: 43190 | D16: 43555 | E16: 43921 | F16: 44286 | G16: 44651 | H16: 45016 | I16: 45382 | J16: 45747 | K16: 46112
A17: Sales | B17: 654.84 | C17: 1017.4 | D17: 1241.73 | E17: 1347.8 | F17: 1409.75 | G17: 2215.87 | H17: 2800.6 | I17: 3160.75 | J17: 3868.77 | K17: 4265.27
A18: Raw Material Cost | B18: 519.38 | C18: 852.76 | D18: 1023.13 | E18: 1114.82 | F18: 1214.89 | G18: 1798.12 | H18: 2316.19 | I18: 2572.29 | J18: 3189.73 | K18: 3591.87
A19: Change in Inventory | B19: 4.17 | C19: 44.22 | D19: -12.31 | E19: 23.75 | F19: 82.48 | G19: 54.59 | H19: 34.17 | I19: 11.1 | J19: 16.93 | K19: 173.92
A20: Power and Fuel | B20: 5.05 | C20: 8.27 | D20: 10.83 | E20: 13.37 | F20: 14.49 | G20: 16.77 | H20: 17.8 | I20: 23.98 | J20: 25.73
A21: Other Mfr. Exp | B21: 18.06 | C21: 26.34 | D21: 36.08 | E21: 39.34 | F21: 44.07 | G21: 71.7 | H21: 97.42 | I21: 96.29 | J21: 114.36
A22: Employee Cost | B22: 35.81 | C22: 52.06 | D22: 63.47 | E22: 65.94 | F22: 72.9 | G22: 102.75 | H22: 133.56 | I22: 131.24 | J22: 159.49 | K22: 181.77
A23: Selling and admin | B23: 14.05 | C23: 21.77 | D23: 22.25 | E23: 16.23 | F23: 19.15 | G23: 30.78 | H23: 39.39 | I23: 39.72 | J23: 46.99
A24: Other Expenses | B24: 8.15 | C24: 8.81 | D24: 11.8 | E24: 13.12 | F24: 5.46 | G24: 32.86 | H24: 23.42 | I24: 20.88 | J24: 21.15 | K24: 230.62
A25: Other Income | B25: 1.45 | C25: 1.59 | D25: 5.45 | E25: -12.24 | F25: 0.9 | G25: 5.71 | H25: 88.06 | I25: 76.45 | J25: 110.73 | K25: 76.93
A26: Depreciation | B26: 5.85 | C26: 8.69 | D26: 11.56 | E26: 18.13 | F26: 20.3 | G26: 20.56 | H26: 23.96 | I26: 37.99 | J26: 29.09 | K26: 38.83
A27: Interest | B27: 10.58 | C27: 20.32 | D27: 26.16 | E27: 31.43 | F27: 30.97 | G27: 37.99 | H27: 43.5 | I27: 51.76 | J27: 46.43 | K27: 24.78
A28: Profit before tax | B28: 43.53 | C28: 64.19 | D28: 29.59 | E28: 46.93 | F28: 70.9 | G28: 164.64 | H28: 227.59 | I28: 274.15 | J28: 363.46 | K28: 448.25
A29: Tax | B29: 8.38 | C29: 16.55 | D29: 10.2 | E29: 10.35 | F29: 14.08 | G29: 16.19 | H29: 23.5 | I29: 31.87 | J29: 50.56 | K29: 69.92
A30: Net profit | B30: 32.7 | C30: 44.09 | D30: 15.49 | E30: 33.18 | F30: 52.47 | G30: 139.39 | H30: 201.1 | I30: 239.19 | J30: 312.39 | K30: 378.8
A31: Dividend Amount | B31: 4.11 | C31: 4.81 | D31: 2.06 | E31: 4.83 | F31: 7.6 | G31: 20.72 | H31: 30.04 | I31: 35.91 | J31: 46.86
A40: Quarters
A41: Report Date | B41: 45291 | C41: 45382 | D41: 45473 | E41: 45565 | F41: 45657 | G41: 45747 | H41: 45838 | I41: 45930 | J41: 46022 | K41: 46112
A42: Sales | B42: 757.77 | C42: 863.41 | D42: 907.86 | E42: 927.42 | F42: 996.42 | G42: 1037.07 | H42: 1039.94 | I42: 1035.5 | J42: 1017.07 | K42: 1172.76
A43: Expenses | B43: 677.42 | C43: 791.25 | D43: 820.19 | E43: 863.93 | F43: 915.69 | G43: 944.88 | H43: 939.31 | I43: 933.49 | J43: 897.29 | K43: 1060.25
A44: Other Income | B44: 15.44 | C44: 24.89 | D44: 6.87 | E44: 40.36 | F44: 28.86 | G44: 35.75 | H44: 30.06 | I44: 26.32 | J44: 11.69 | K44: 8.86
A45: Depreciation | B45: 9.02 | C45: 12.48 | D45: 6.52 | E45: 7.18 | F45: 7.64 | G45: 7.75 | H45: 8.71 | I45: 9.23 | J45: 9.84 | K45: 11.05
A46: Interest | B46: 13 | C46: 12.35 | D46: 12.96 | E46: 11.95 | F46: 12.84 | G46: 5.62 | H46: 6.05 | I46: 7.82 | J46: 6.54 | K46: 4.37
A47: Profit before tax | B47: 73.77 | C47: 72.22 | D47: 75.06 | E47: 84.72 | F47: 89.11 | G47: 114.57 | H47: 115.93 | I47: 111.28 | J47: 115.09 | K47: 105.95
A48: Tax | B48: 12.3 | C48: 2.8 | D48: 7.06 | E48: 12.8 | F48: 11.05 | G48: 19.65 | H48: 22.87 | I48: 15.31 | J48: 17.6 | K48: 14.14
A49: Net profit | B49: 60.27 | C49: 68.98 | D49: 67.33 | E49: 72 | F49: 77.93 | G49: 95.13 | H49: 93.26 | I49: 95.99 | J49: 97.67 | K49: 91.88
A50: Operating Profit | B50: 80.35 | C50: 72.16 | D50: 87.67 | E50: 63.49 | F50: 80.73 | G50: 92.19 | H50: 100.63 | I50: 102.01 | J50: 119.78 | K50: 112.51
A55: BALANCE SHEET
A56: Report Date | B56: 42825 | C56: 43190 | D56: 43555 | E56: 43921 | F56: 44286 | G56: 44651 | H56: 45016 | I56: 45382 | J56: 45747 | K56: 46112
A57: Equity Share Capital | B57: 13.69 | C57: 13.74 | D57: 13.75 | E57: 13.81 | F57: 13.81 | G57: 13.81 | H57: 13.81 | I57: 13.81 | J57: 14.76 | K57: 14.76
A58: Reserves | B58: 136.45 | C58: 175.94 | D58: 185.57 | E58: 211.37 | F58: 255.12 | G58: 373.04 | H58: 575.12 | I58: 823.59 | J58: 2055.15 | K58: 2436.87
...

Sheet Lookup
A1: Company Name | B1: CD_NSE Symbol | C1: Accord Code | D1: CD_Bloomberg Code | E1: CD_ISIN No
A2: 3I Infotech Ltd | B2: 3IINFOLTD | C2: 132628 | D2: III IN | E2: INE748C01038
A3: 3M India Ltd | B3: 3MINDIA | C3: 123395 | D3: 3M IN | E3: INE470A01017
A4: 5Paisa Capital Ltd | B4: 5PAISA | C4: 228972 | D4: 5PAISA IN | E4: INE618L01018
A5: 63 Moons Technologies Ltd | B5: 63MOONS | C5: 126881 | D5: 63MOONS IN | E5: INE111B01023
A6: Aarti Drugs Ltd | B6: AARTIDRUGS | C6: 124348 | D6: ARTD IN | E6: INE767A01016
A7: Aarti Industries Ltd | B7: AARTIIND | C7: 124208 | D7: ARTO IN | E7: INE769A01020
A8: Aarti Surfactants Ltd | B8: AARTISURF | C8: 299121 | D8: AARTISUR IN | E8: INE09EO01013
A9: Aavas Financiers Ltd | B9: AAVAS | C9: 267615 | D9: AAVAS IN | E9: INE216P01012
A10: ABB India Ltd | B10: ABB | C10: 100002 | D10: ABB IN | E10: INE117A01022
A11: Abbott India Ltd | B11: ABBOTINDIA | C11: 100488 | D11: BOOT IN | E11: INE358A01014
A12: ACC Ltd | B12: ACC | C12: 100410 | D12: ACC IN | E12: INE012A01025
A13: Accelya Solutions India Ltd | B13: ACCELYA | C13: 132268 | D13: ACCELYA IN | E13: INE793A01012
... A25: Aditya Birla Sun Life AMC Ltd | B25: ABSLAMC | C25: 209979 | D25: ABSLAMC IN | E25: INE404A01024
A26: Aditya Vision Ltd | C26: 283206 | D26: AVL IN | E26: INE679V01019
A27: Ador Welding Ltd | B27: ADORWELD | C27: 117041 | D27: AWL IN | E27: INE045A01017
A28: Advanced Enzyme Technologies Ltd | B28: ADVENZYMES | C28: 207679 | D28: ADVENZY IN | E28: INE837H01020
A29: Aegis Logistics Ltd | B29: AEGISCHEM | C29: 100003 | D29: AGIS IN | E29: INE208C01025
A30: Affle (India) Ltd | B30: AFFLE | C30: 229238 | D30: AFFLE IN | E30: INE00WC01027
A31: Agarwal Industrial Corporation Ltd | B31: AGARIND | C31: 131921 | D31: AGAR IN | E31: INE204E01012
A32: Agro Tech Foods Ltd | B32: ATFL | C32: 100215 | D32: ATFL IN | E32: INE209A01019
A33: Ahluwalia Contracts (India) Ltd | B33: AHLUCONT | C33: 132811 | D33: AHLU IN | E33: INE758C01029
A34: AIA Engineering Ltd | B34: AIAENG | C34: 132683 | D34: AIAE IN | E34: INE212H01026
A35: Ajanta Pharma Ltd | B35: AJANTPHARM | C35: 132331 | D35: AJP IN | E35: INE031B01049
A36: Ajmera Realty & Infra India Ltd | B36: AJMERA | C36: 113349 | D36: AREAL IN | E36: INE298G01027
A37: Akzo Nobel India Ltd | B37: AKZOINDIA | C37: 100710 | D37: AKZO IN | E37: INE133A01011
A38: Alembic Ltd | B38: ALEMBICLTD | C38: 106235 | D38: ALBC IN | E38: INE426A01027
... A51: AMI Organics Ltd | B51: AMIORG | C51: 232793 | D51: AMIORG IN | E51: INE00FF01017
A52: Amines & Plasticizers Ltd | C52: 106248 | D52: ANPL IN | E52: INE275D01022
A53: Amrutanjan Health Care Ltd | B53: AMRUTANJAN | C53: 190006 | D53: ARJN IN | E53: INE098F01031
A54: Anand Rathi Wealth Ltd | B54: ANANDRATHI | C54: 226156 | D54: ANANDRAT IN | E54: INE463V01026
A55: Anant Raj Ltd | B55: ANANTRAJ | C55: 115055 | D55: ARCP IN | E55: INE242C01024
A56: Andhra Paper Ltd | B56: ANDHRAPAP | C56: 102330 | D56: ANHPR IN | E56: INE435A01028
A57: Andhra Petrochemicals Ltd | B57: ANDHRAPET | C57: 100012 | D57: ANDP IN | E57: INE714B01016
A58: Andrew Yule & Company Ltd | B58: ANDREWYU | C58: 126173 | D58: ANY IN | E58: INE449C01025
A59: Angel One Ltd | B59: ANGELONE | C59: 209902 | D59: ANGELONE IN | E59: INE732I01013
A60: Anjani Portland Cement Ltd | B60: APCL | C60: 118091 | D60: SHZC IN | E60: INE071F01012
A61: Antony Waste Handling Cell Ltd | B61: AWHCL | C61: 277374 | D61: AWHCL IN | E61: INE01BK01022
A62: Anuh Pharma Ltd | C62: 106260 | D62: ANUH IN | E62: INE489G01022
A63: Anupam Rasayan India Ltd | B63: ANURAS | C63: 226328 | D63: ANURAS IN | E63: INE930P01018
...

Sheet Cover
A1: GRAVITA INDIA LTD
A2: Metal & Metal Products | TIKONA CAPITAL
A4: CMP (₹) | B4: 1777
A5: Target (₹) | B5: 2380
A6: Upside | B6: 33.9%
A7: Rating | B7: BUY
A8: Market Cap (₹ Cr) | B8: 13112.41
A9: Shares (Cr) | B9: 7.38
A10: Base Year | B10: FY26
A12: RATING: BUY | Target: ₹2,380 | Upside: 33.9%
A14: Gravita is poised to benefit from India's circular economy push and regulatory tailwinds in battery recycling. The company's capacity doubling to 7 lakh MTPA by FY28, diversification into lithium-ion and rubber recycling, and improving domestic scrap availability provide strong growth visibility. Management's Vision 2029 targets 25%+ volume CAGR with expanding non-lead contribution create multiple re-rating catalysts.
A19: KEY CATALYSTS
A20: • Completion of 1.25 lakh MTPA lead capacity by Q4 FY26
A21: • Lithium-ion battery recycling plant commissioning at Mundra
A22: • Copper recycling plant setup at Mandvi, Gujarat (29,400 MTPA)
A23: • RMIL acquisition synergies and integration completion
A25: KEY RISKS
A26: • Regulatory delays in capacity expansion approvals
A27: • Raw material scrap availability fluctuations
A28: • Commodity price volatility affecting margins
A29: • New vertical execution and scaling risks
A31: SAARTHI SCORE: 78.0/100 → BUY

Sheet Assumptions
A1: Particulars | B1: FY21A | C1: FY22A | D1: FY23A | E1: FY24A | F1: FY25A | G1: FY26A | H1: FY27E | I1: FY28E | J1: FY29E | K1: FY30E | L1: FY31E
A2: Revenue Growth % | H2: 16.5 | I2: 22 | J2: 18.5 | K2: 15.2 | L2: 12.8
A3: RM % of Revenue | H3: 83.2 | I3: 82.5 | J3: 81.8 | K3: 81.2 | L3: 80.8
A4: Employee % of Revenue | H4: 4.1 | I4: 3.9 | J4: 3.8 | K4: 3.7 | L4: 3.6
A5: Power & Fuel % | H5: 0.9 | I5: 0.8 | J5: 0.8 | K5: 0.8 | L5: 0.7
A6: Other Mfg % | H6: 2.1 | I6: 2 | J6: 1.9 | K6: 1.8 | L6: 1.8
A7: Selling & Admin % | H7: 1 | I7: 1 | J7: 1 | K7: 1 | L7: 1
A8: Other Expenses % | H8: 1.2 | I8: 1.1 | J8: 1 | K8: 0.9 | L8: 0.9
A9: Chg in Inventory % | H9: 3.8 | I9: 4.2 | J9: 3.5 | K9: 3.2 | L9: 2.8
A10: Depreciation (₹ Cr) | H10: 58 | I10: 78 | J10: 105 | K10: 128 | L10: 148
A11: Interest (₹ Cr) | H11: 32 | I11: 45 | J11: 52 | K11: 58 | L11: 62
A12: Other Income (₹ Cr) | H12: 95 | I12: 118 | J12: 142 | K12: 165 | L12: 185
A13: Tax Rate % | H13: 15.8 | I13: 16.2 | J13: 16.5 | K13: 17 | L13: 17.5
... A16: Inventory Days | H16: 82 | I16: 78 | J16: 75 | K16: 72 | L16: 70
A18: VALUATION ASSUMPTIONS
A19: WACC % | B19: 11.8
A20: Terminal Growth % | B20: 4.2
A21: Target PE (x) | B21: 28.5
A22: Target EV/EBITDA (x) | B22: 18.2
A23: Dividend Payout % | B23: 15
A25: RATIONALE
A26: Growth driven by 7 lakh MTPA capacity by FY28, new verticals (lithium-ion, rubber, copper), improving domestic scrap availability, and rising non-lead contribution to 30% by FY29. Management targets 25%+ volume CAGR and 35%+ profit growth backed by Rs1,225cr capex.

Sheet P&L
A1: All figures in ₹ Cr
A2: Particulars | B2: FY21A | C2: FY22A | D2: FY23A | E2: FY24A | F2: FY25A | G2: FY26A | H2: FY27E | I2: FY28E | J2: FY29E | K2: FY30E | L2: FY31E
A3: Revenue | B3: ='Data Sheet'!F17 | C3: ='Data Sheet'!G17 | D3: ='Data Sheet'!H17 | E3: ='Data Sheet'!I17 | F3: ='Data Sheet'!J17 | G3: ='Data Sheet'!K17 | H3: =G3*(1+'Assumptions'!H2/100) | I3: =H3*(1+'Assumptions'!I2/100) | J3: =I3*(1+'Assumptions'!J2/100) | K3: =J3*(1+'Assumptions'!K2/100) | L3: =K3*(1+'Assumptions'!L2/100)
A4: Raw Material Cost | B4: ='Data Sheet'!F18 | C4: ='Data Sheet'!G18 | D4: ='Data Sheet'!H18 | E4: ='Data Sheet'!I18 | F4: ='Data Sheet'!J18 | G4: ='Data Sheet'!K18 | H4: =H3*'Assumptions'!H3/100 | I4: =I3*'Assumptions'!I3/100 | J4: =J3*'Assumptions'!J3/100 | K4: =K3*'Assumptions'!K3/100 | L4: =L3*'Assumptions'!L3/100
A5: Chg in Inventory | B5: ='Data Sheet'!F19 | C5: ='Data Sheet'!G19 | D5: ='Data Sheet'!H19 | E5: ='Data Sheet'!I19 | F5: ='Data Sheet'!J19 | G5: ='Data Sheet'!K19 | H5: =H3*'Assumptions'!H9/100 | I5: =I3*'Assumptions'!I9/100 | J5: =J3*'Assumptions'!J9/100 | K5: =K3*'Assumptions'!K9/100 | L5: =L3*'Assumptions'!L9/100
A6: Employee Cost | B6: ='Data Sheet'!F22 | C6: ='Data Sheet'!G22 | D6: ='Data Sheet'!H22 | E6: ='Data Sheet'!I22 | F6: ='Data Sheet'!J22 | G6: ='Data Sheet'!K22 | H6: =H3*'Assumptions'!H4/100 | I6: =I3*'Assumptions'!I4/100 | J6: =J3*'Assumptions'!J4/100 | K6: =K3*'Assumptions'!K4/100 | L6: =L3*'Assumptions'!L4/100
A7: Power & Fuel | B7: ='Data Sheet'!F20 | C7: ='Data Sheet'!G20 | D7: ='Data Sheet'!H20 | E7: ='Data Sheet'!I20 | F7: ='Data Sheet'!J20 | G7: ='Data Sheet'!K20 | H7: =H3*'Assumptions'!H5/100 | I7: =I3*'Assumptions'!I5/100 | J7: =J3*'Assumptions'!J5/100 | K7: =K3*'Assumptions'!K5/100 | L7: =L3*'Assumptions'!L5/100
A8: Other Mfg Exp | B8: ='Data Sheet'!F21 | C8: ='Data Sheet'!G21 | D8: ='Data Sheet'!H21 | E8: ='Data Sheet'!I21 | F8: ='Data Sheet'!J21 | G8: ='Data Sheet'!K21 | H8: =H3*'Assumptions'!H6/100 | I8: =I3*'Assumptions'!I6/100 | J8: =J3*'Assumptions'!J6/100 | K8: =K3*'Assumptions'!K6/100 | L8: =L3*'Assumptions'!L6/100
A9: Selling & Admin | B9: ='Data Sheet'!F23 | C9: ='Data Sheet'!G23 | D9: ='Data Sheet'!H23 | E9: ='Data Sheet'!I23 | F9: ='Data Sheet'!J23 | G9: ='Data Sheet'!K23 | H9: =H3*'Assumptions'!H7/100 | I9: =I3*'Assumptions'!I7/100 | J9: =J3*'Assumptions'!J7/100 | K9: =K3*'Assumptions'!K7/100 | L9: =L3*'Assumptions'!L7/100
A10: Other Expenses | B10: ='Data Sheet'!F24 | C10: ='Data Sheet'!G24 | D10: ='Data Sheet'!H24 | E10: ='Data Sheet'!I24 | F10: ='Data Sheet'!J24 | G10: ='Data Sheet'!K24 | H10: =H3*'Assumptions'!H8/100 | I10: =I3*'Assumptions'!I8/100 | J10: =J3*'Assumptions'!J8/100 | K10: =K3*'Assumptions'!K8/100 | L10: =L3*'Assumptions'!L8/100
A11: Total Expenses | B11: =SUM(B4:B10) | C11: =SUM(C4:C10) | D11: =SUM(D4:D10) | E11: =SUM(E4:E10) | F11: =SUM(F4:F10) | G11: =SUM(G4:G10) | H11: =SUM(H4:H10) | I11: =SUM(I4:I10) | ... L11: =SUM(L4:L10)
A12: EBITDA | B12: =B3-B11 | C12: =C3-C11 | D12: =D3-D11 | E12: =E3-E11 | F12: =F3-F11 | G12: =G3-G11 | H12: =H3-H11 | I12: =I3-I11 | ... L12: =L3-L11
A13: EBITDA Margin % | B13: =IF(B3=0,0,B12/B3) | C13: =IF(C3=0,0,C12/C3) | D13: =IF(D3=0,0,D12/D3) | E13: =IF(E3=0,0,E12/E3) | F13: =IF(F3=0,0,F12/F3) | G13: =IF(G3=0,0,G12/G3) | H13: =IF(H3=0,0,H12/H3) | I13: =IF(I3=0,0,I12/I3) | ... L13: =IF(L3=0,0,L12/L3)
A14: Other Income | B14: ='Data Sheet'!F25 | C14: ='Data Sheet'!G25 | D14: ='Data Sheet'!H25 | E14: ='Data Sheet'!I25 | F14: ='Data Sheet'!J25 | G14: ='Data Sheet'!K25 | H14: ='Assumptions'!H12 | I14: ='Assumptions'!I12 | J14: ='Assumptions'!J12 | K14: ='Assumptions'!K12 | L14: ='Assumptions'!L12
A15: Depreciation | B15: ='Data Sheet'!F26 | C15: ='Data Sheet'!G26 | D15: ='Data Sheet'!H26 | E15: ='Data Sheet'!I26 | F15: ='Data Sheet'!J26 | G15: ='Data Sheet'!K26 | H15: ='Assumptions'!H10 | I15: ='Assumptions'!I10 | J15: ='Assumptions'!J10 | K15: ='Assumptions'!K10 | L15: ='Assumptions'!L10
A16: EBIT | B16: =B12+B14-B15 | C16: =C12+C14-C15 | D16: =D12+D14-D15 | E16: =E12+E14-E15 | F16: =F12+F14-F15 | G16: =G12+G14-G15 | H16: =H12+H14-H15 | I16: =I12+I14-I15 | ... L16: =L12+L14-L15
A17: Finance Cost | B17: ='Data Sheet'!F27 | C17: ='Data Sheet'!G27 | D17: ='Data Sheet'!H27 | E17: ='Data Sheet'!I27 | F17: ='Data Sheet'!J27 | G17: ='Data Sheet'!K27 | H17: ='Assumptions'!H11 | I17: ='Assumptions'!I11 | J17: ='Assumptions'!J11 | K17: ='Assumptions'!K11 | L17: ='Assumptions'!L11
A18: Profit Before Tax | B18: =B16-B17 | C18: =C16-C17 | D18: =D16-D17 | E18: =E16-E17 | F18: =F16-F17 | G18: =G16-G17 | H18: =H16-H17 | I18: =I16-I17 | ... L18: =L16-L17
A19: Tax | B19: ='Data Sheet'!F29 | C19: ='Data Sheet'!G29 | D19: ='Data Sheet'!H29 | E19: ='Data Sheet'!I29 | F19: ='Data Sheet'!J29 | G19: ='Data Sheet'!K29 | H19: =MAX(0,H18*'Assumptions'!H13/100) | I19: =MAX(0,I18*'Assumptions'!I13/100) | J19: =MAX(0,J18*'Assumptions'!J13/100) | K19: =MAX(0,K18*'Assumptions'!K13/100) | L19: =MAX(0,L18*'Assumptions'!L13/100)
A20: Profit After Tax (PAT) | B20: =B18-B19 | C20: =C18-C19 | D20: =D18-D19 | E20: =E18-E19 | F20: =F18-F19 | G20: =G18-G19 | H20: =H18-H19 | I20: =I18-I19 | ... L20: =L18-L19
A21: PAT Margin % | B21: =IF(B3=0,0,B20/B3) | C21: =IF(C3=0,0,C20/C3) | D21: =IF(D3=0,0,D20/D3) | E21: =IF(E3=0,0,E20/E3) | F21: =IF(F3=0,0,F20/F3) | G21: =IF(G3=0,0,G20/G3) | H21: =IF(H3=0,0,H20/H3) | I21: =IF(I3=0,0,I20/I3) | ... L21: =IF(L3=0,0,L20/L3)
A22: PAT Growth % | C22: =IF(B20<=0,0,(C20/B20)-1) | D22: =IF(C20<=0,0,(D20/C20)-1) | E22: =IF(D20<=0,0,(E20/D20)-1) | F22: =IF(E20<=0,0,(F20/E20)-1) | G22: =IF(F20<=0,0,(G20/F20)-1) | H22: =IF(G20<=0,0,(H20/G20)-1) | I22: =IF(H20<=0,0,(I20/H20)-1) | J22: =IF(I20<=0,0,(J20/I20)-1) | ... L22: =IF(K20<=0,0,(L20/K20)-1)
A23: EPS (₹) | B23: =B20/7.38 | C23: =C20/7.38 | D23: =D20/7.38 | E23: =E20/7.38 | F23: =F20/7.38 | G23: =G20/7.38 | H23: =H20/7.38 | I23: =I20/7.38 | ... L23: =L20/7.38

Sheet Balance Sheet
A1: All figures in ₹ Cr
A2: Particulars | B2: FY21A | C2: FY22A | D2: FY23A | E2: FY24A | F2: FY25A | G2: FY26A | H2: FY27E | I2: FY28E | J2: FY29E | K2: FY30E | L2: FY31E
A3: Share Capital | B3: ='Data Sheet'!F57 | C3: ='Data Sheet'!G57 | D3: ='Data Sheet'!H57 | E3: ='Data Sheet'!I57 | F3: ='Data Sheet'!J57 | G3: ='Data Sheet'!K57 | H3: 15 | I3: 15 | J3: 15 | K3: 15 | L3: 15
A4: Reserves | B4: ='Data Sheet'!F58 | C4: ='Data Sheet'!G58 | D4: ='Data Sheet'!H58 | E4: ='Data Sheet'!I58 | F4: ='Data Sheet'!J58 | G4: ='Data Sheet'!K58 | H4: 2858 | I4: 3485 | J4: 4295 | K4: 5187 | L4: 6145
A5: Total Equity | B5: =B3+B4 | C5: =C3+C4 | D5: =D3+D4 | E5: =E3+E4 | F5: =F3+F4 | G5: =G3+G4 | H5: =H3+H4 | I5: =I3+I4 | ... L5: =L3+L4
A6: Borrowings | B6: ='Data Sheet'!F59 | C6: ='Data Sheet'!G59 | D6: ='Data Sheet'!H59 | E6: ='Data Sheet'!I59 | F6: ='Data Sheet'!J59 | G6: ='Data Sheet'!K59 | H6: 920 | I6: 1285 | J6: 1450 | K6: 1520 | L6: 1580
A7: Other Liabilities | B7: ='Data Sheet'!F60 | C7: ='Data Sheet'!G60 | D7: ='Data Sheet'!H60 | E7: ='Data Sheet'!I60 | F7: ='Data Sheet'!J60 | G7: ='Data Sheet'!K60 | H7: 285 | I7: 365 | J7: 425 | K7: 485 | L7: 535
A8: Total Liabilities & Equity | B8: =B5+B6+B7 | C8: =C5+C6+C7 | D8: =D5+D6+D7 | E8: =E5+E6+E7 | F8: =F5+F6+F7 | G8: =G5+G6+G7 | H8: =H5+H6+H7 | I8: =I5+I6+I7 | ... L8: =L5+L6+L7
A10: APPLICATION OF FUNDS
A11: Net Block | B11: ='Data Sheet'!F62 | C11: ='Data Sheet'!G62 | D11: ='Data Sheet'!H62 | E11: ='Data Sheet'!I62 | F11: ='Data Sheet'!J62 | G11: ='Data Sheet'!K62 | H11: 1285 | I11: 1840 | J11: 2185 | K11: 2377 | L11: 2509
A12: CWIP | B12: ='Data Sheet'!F63 | C12: ='Data Sheet'!G63 | D12: ='Data Sheet'!H63 | E12: ='Data Sheet'!I63 | F12: ='Data Sheet'!J63 | G12: ='Data Sheet'!K63 | H12: 62 | I12: 85 | J12: 95 | K12: 72 | L12: 58
A13: Investments | B13: ='Data Sheet'!F64 | C13: ='Data Sheet'!G64 | D13: ='Data Sheet'!H64 | E13: ='Data Sheet'!I64 | F13: ='Data Sheet'!J64 | G13: ='Data Sheet'!K64 | H13: 450 | I13: 520 | J13: 610 | K13: 725 | L13: 820
A14: Trade Receivables | B14: ='Data Sheet'!F67 | C14: ='Data Sheet'!G67 | D14: ='Data Sheet'!H67 | E14: ='Data Sheet'!I67 | F14: ='Data Sheet'!J67 | G14: ='Data Sheet'!K67 | H14: ='P&L'!H3*'Assumptions'!H15/365 | I14: ='P&L'!I3*'Assumptions'!I15/365 | J14: ='P&L'!J3*'Assumptions'!J15/365 | K14: ='P&L'!K3*'Assumptions'!K15/365 | L14: ='P&L'!L3*'Assumptions'!L15/365
A15: Inventory | B15: ='Data Sheet'!F68 | C15: ='Data Sheet'!G68 | D15: ='Data Sheet'!H68 | E15: ='Data Sheet'!I68 | F15: ='Data Sheet'!J68 | G15: ='Data Sheet'!K68 | H15: ='P&L'!H4*'Assumptions'!H16/365 | I15: ='P&L'!I4*'Assumptions'!I16/365 | J15: ='P&L'!J4*'Assumptions'!J16/365 | K15: ='P&L'!K4*'Assumptions'!K16/365 | L15: ='P&L'!L4*'Assumptions'!L16/365
A16: Cash & Bank (Plug) | B16: ='Data Sheet'!F69 | C16: ='Data Sheet'!G69 | D16: ='Data Sheet'!H69 | E16: ='Data Sheet'!I69 | F16: ='Data Sheet'!J69 | G16: ='Data Sheet'!K69 | H16: =H8-H11+H12+H13+H14+H15-H17 | I16: =I8-I11+I12+I13+I14+I15-I17 | J16: =J8-J11+J12+J13+J14+J15-J17 | K16: =K8-K11+K12+K13+K14+K15-K17 | L16: =L8-L11+L12+L13+L14+L15-L17
A17: Other Assets | B17: ='Data Sheet'!F65-'Data Sheet'!F67-'Data Sheet'!F68-'Data Sheet'!F69 | C17: ='Data Sheet'!G65-'Data Sheet'!G67-'Data Sheet'!G68-'Data Sheet'!G69 | D17: ='Data Sheet'!H65-'Data Sheet'!H67-'Data Sheet'!H68-'Data Sheet'!H69 | E17: ='Data Sheet'!I65-'Data Sheet'!I67-'Data Sheet'!I68-'Data Sheet'!I69 | F17: ='Data Sheet'!J65-'Data Sheet'!J67-'Data Sheet'!J68-'Data Sheet'!J69 | G17: ='Data Sheet'!K65-'Data Sheet'!K67-'Data Sheet'!K68-'Data Sheet'!K69 | H17: 2580 | I17: 3420 | J17: 4280 | K17: 5050 | L17: 5720
A18: Total Assets | B18: =B11+B12+B13+B14+B15+B16+B17 | C18: =C11+C12+C13+C14+C15+C16+C17 | D18: =D11+D12+D13+D14+D15+D16+D17 | E18: =E11+E12+E13+E14+E15+E16+E17 | F18: =F11+F12+F13+F14+F15+F16+F17 | G18: =G11+G12+G13+G14+G15+G16+G17 | H18: =H11+H12+H13+H14+H15+H16+H17 | I18: =I11+I12+I13+I14+I15+I16+I17 | ... L18: =L11+L12+L13+L14+L15+L16+L17
A19: CHECK (TA - TL&E = 0) | B19: =B18-B8 | C19: =C18-C8 | D19: =D18-D8 | E19: =E18-E8 | F19: =F18-F8 | G19: =G18-G8 | H19: =H18-H8 | I19: =I18-I8 | ... L19: =L18-L8

Sheet Cash Flow
